2015-04-14 21:45:47,194 - snh.management.commands.cronfb - INFO - Will run the Facebook harvesters.
2015-04-14 21:45:47,196 - snh.management.commands.cronfb - ERROR - Highest exception for the facebook cron. Not good.
Traceback (most recent call last):
  File "C:\Users\Sam\Documents\ASPIRA\Social-Network-Harvester\SocialNetworkHarvester\snh\management\commands\cronfb.py", line 23, in handle
    facebookch.run_facebook_harvester()
  File "C:\Users\Sam\Documents\ASPIRA\Social-Network-Harvester\SocialNetworkHarvester\snh\management\commands\cronharvester\facebookch.py", line 40, in run_facebook_harvester
    last_seen_at = datetime.now()
  File "C:\Users\Sam\Documents\ASPIRA\py27env\lib\site-packages\django\db\models\manager.py", line 138, in create
    return self.get_query_set().create(**kwargs)
  File "C:\Users\Sam\Documents\ASPIRA\py27env\lib\site-packages\django\db\models\query.py", line 358, in create
    obj = self.model(**kwargs)
  File "C:\Users\Sam\Documents\ASPIRA\py27env\lib\site-packages\django\db\models\base.py", line 352, in __init__
    setattr(self, field.name, rel_obj)
  File "C:\Users\Sam\Documents\ASPIRA\py27env\lib\site-packages\django\db\models\fields\related.py", line 331, in __set__
    self.field.name, self.field.rel.to._meta.object_name))
ValueError: Cannot assign "'a2efe4ab349f676bbd5b047481d49c68'": "User.oauth_token" must be a "OAuthToken" instance.
2015-04-14 21:45:47,197 - snh.management.commands.cronfb - INFO - The harvest has end for the Facebook harvesters.
2015-04-14 21:47:54,657 - snh.management.commands.cronfb - INFO - Will run the Facebook harvesters.
2015-04-14 21:47:54,660 - snh.management.commands.cronfb - ERROR - Highest exception for the facebook cron. Not good.
Traceback (most recent call last):
  File "C:\Users\Sam\Documents\ASPIRA\Social-Network-Harvester\SocialNetworkHarvester\snh\management\commands\cronfb.py", line 23, in handle
    facebookch.run_facebook_harvester()
  File "C:\Users\Sam\Documents\ASPIRA\Social-Network-Harvester\SocialNetworkHarvester\snh\management\commands\cronharvester\facebookch.py", line 42, in run_facebook_harvester
    last_seen_at = datetime.now()
  File "C:\Users\Sam\Documents\ASPIRA\py27env\lib\site-packages\django\db\models\manager.py", line 138, in create
    return self.get_query_set().create(**kwargs)
  File "C:\Users\Sam\Documents\ASPIRA\py27env\lib\site-packages\django\db\models\query.py", line 358, in create
    obj = self.model(**kwargs)
  File "C:\Users\Sam\Documents\ASPIRA\py27env\lib\site-packages\django\db\models\base.py", line 352, in __init__
    setattr(self, field.name, rel_obj)
  File "C:\Users\Sam\Documents\ASPIRA\py27env\lib\site-packages\django\db\models\fields\related.py", line 331, in __set__
    self.field.name, self.field.rel.to._meta.object_name))
ValueError: Cannot assign "'a2efe4ab349f676bbd5b047481d49c68'": "User.oauth_token" must be a "OAuthToken" instance.
2015-04-14 21:47:54,661 - snh.management.commands.cronfb - INFO - The harvest has end for the Facebook harvesters.
2015-04-14 21:54:58,940 - snh.management.commands.cronfb - INFO - Will run the Facebook harvesters.
2015-04-14 21:54:58,943 - snh.management.commands.cronfb - ERROR - Highest exception for the facebook cron. Not good.
Traceback (most recent call last):
  File "C:\Users\Sam\Documents\ASPIRA\Social-Network-Harvester\SocialNetworkHarvester\snh\management\commands\cronfb.py", line 23, in handle
    facebookch.run_facebook_harvester()
  File "C:\Users\Sam\Documents\ASPIRA\Social-Network-Harvester\SocialNetworkHarvester\snh\management\commands\cronharvester\facebookch.py", line 42, in run_facebook_harvester
    last_seen_at = datetime.now()
  File "C:\Users\Sam\Documents\ASPIRA\py27env\lib\site-packages\django\db\models\manager.py", line 138, in create
    return self.get_query_set().create(**kwargs)
  File "C:\Users\Sam\Documents\ASPIRA\py27env\lib\site-packages\django\db\models\query.py", line 358, in create
    obj = self.model(**kwargs)
  File "C:\Users\Sam\Documents\ASPIRA\py27env\lib\site-packages\django\db\models\base.py", line 352, in __init__
    setattr(self, field.name, rel_obj)
  File "C:\Users\Sam\Documents\ASPIRA\py27env\lib\site-packages\django\db\models\fields\related.py", line 331, in __set__
    self.field.name, self.field.rel.to._meta.object_name))
ValueError: Cannot assign "'a2efe4ab349f676bbd5b047481d49c68'": "User.oauth_token" must be a "OAuthToken" instance.
2015-04-14 21:54:58,944 - snh.management.commands.cronfb - INFO - The harvest has end for the Facebook harvesters.
2015-04-16 15:02:12,582 - snh.management.commands.cronfb - INFO - Will run the Facebook harvesters.
2015-04-16 15:02:12,582 - snh.management.commands.cronfb - ERROR - Highest exception for the facebook cron. Not good.
Traceback (most recent call last):
  File "C:\Users\Sam\Documents\ASPIRA\Social-Network-Harvester\SocialNetworkHarvester\snh\management\commands\cronfb.py", line 23, in handle
    facebookch.run_facebook_harvester()
  File "C:\Users\Sam\Documents\ASPIRA\Social-Network-Harvester\SocialNetworkHarvester\snh\management\commands\cronharvester\facebookch.py", line 33, in run_facebook_harvester
    fanuser = FanUser.objects.all()[0]
  File "C:\Users\Sam\Documents\ASPIRA\py27env\lib\site-packages\django\db\models\query.py", line 190, in __getitem__
    return list(qs)[0]
IndexError: list index out of range
2015-04-16 15:02:12,582 - snh.management.commands.cronfb - INFO - The harvest has end for the Facebook harvesters.
